Workbook

Sheet AI response evaluation 
A1: Cell Biology Misconceptions - AI Model Evaluation
A3: Dataset Type: AI Biological Knowledge Evaluation
A4: Domain: Cell Biology & Misconceptions
A6: Dataset Information :
A7: Data Collection Period: 15–30 Nov 2025.
A8: Models Evaluated: ChatGPT-5, Claude (latest public), Copilot.
A9: Evaluation Method: Responses copied verbatim; assessed manually and scored numerically
A11: Scoring Rubric:
A13: Category Scoring (1–5 per response)
A15: Score | B15: Meaning
A16: 1 | B16: Poor — incorrect or unclear
A17: 2 | B17: Fair — partly correct or vague
A18: 3 | B18: Good — mostly correct
A19: 4 | B19: Very Good — correct and clear
A20: 5 | B20: Excellent — correct, clear, complete
A22: Final Correctness Score (0–2)
A24: Final Score | B24: Meaning
A25: 2 | B25: Fully correct – no major issues
A26: 1 | B26: Partially correct – minor clarity/completeness issues
A27: 0 | B27: Incorrect or misleading
A29: Note: Length of response does not affect scoring unless it causes confusion or misinformation.
A31: S. No. | B31: Misconceptions | C31: Prompt | D31: AI Model | E31: AI Response | F31: Accuracy (1-5) | G31: Clarity (1-5) | H31: Completeness (1-5) | I31: Score (0–2) | J31: Comment (if any) | K31: Correction (if any) | L31: Source Used | M31: Error Type
A32: 1 | B32: DNA is larger than a cell. | C32: Is DNA larger than a cell? | D32: ChatGPT-5 | E32: No. A cell is massively larger. DNA is a long molecule inside the cell nucleus (or nucleoid), but the cell itself is much bigger. | F32: 5 | G32: 5 | H32: 4 | I32: 2 | J32: Correct answer; short and clear. (Model could also mention size for example to make it more clear and precise. For example: Human cell: ~10–100 micrometers in diameter. - DNA double helix: ~2 nanometers wide. - That’s a difference of thousands of times — the cell is vastly larger than the DNA inside it.) | K32: No correction needed. (Optional: add numeric comparison: cell ~10–100 µm vs DNA ~2 m when stretched for clarity.) | L32: Khan Academy “Levels of DNA organization” & Khan Academy. ""Organelles in eukaryotic cells."" (accessed 2025-11-17); Link: https://www.khanacademy.org/test-prep/mcat/cells/eukaryotic-cells/a/organelles | M32: No error
D33: Claude | E33: No. DNA is inside cells. A single DNA molecule can be quite long when stretched out (human DNA is about 2 meters total if you unwound it all), but it's tightly coiled and packaged inside the cell's nucleus. The cell itself is much larger as a complete structure. | F33: 5 | G33: 5 | H33: 5 | I33: 2 | J33: Most balanced answer; correct and complete (Model could add the comparison of size of a cell and its DNA to make it more clear.) | K33: No correction needed. | L33: OpenStax Biology 2e, Ch.4 “Eukaryotic Cells” (accessed 2025-11-17) | M33: No error
D34: Copilot | E34: Yes, DNA is longer than a cell, but thanks to its microscopic width and efficient packaging, it fits neatly inside. - DNA vs. Cell Size - DNA molecule length: If you stretched out all the DNA from a single human cell, it would be about 2 meters long. - Cell size: A typical human cell is only about 10–100 micrometers (µm) across — that’s a millionth of a meter. - DNA is much longer than the cell itself when fully extended. - However, DNA is extremely thin (about 2 nanometers wide), so it can be tightly packed and coiled inside the cell’s nucleus. - Specialized proteins (like histones) help wrap DNA into compact structures called chromosomes, allowing it to fit inside the tiny cell. | F34: 4 | G34: 4 | H34: 4 | I34: 1 | J34: The answer is scientifically correct but confusing. The model starts with “Yes, DNA is longer than a cell,” which reinforces the misconception. It should clearly distinguish between the physical length of the DNA molecule when stretched out and the actual size/volume of DNA compared to a whole cell. | K34: Correct version should state: Lengthwise: DNA can be longer than a cell when stretched out, but Size/volume-wise: A cell is far larger because DNA is tightly packaged into chromatin and chromosomes. Therefore, overall DNA is not larger than a cell. | L34: Same as above | M34: Misleading phrasing
A35: 2 | B35: Plants do not respire; only animals respire. | C35: Do plants respire? | D35: ChatGPT-5 | E35: Yes. Plants respire 24/7. They take in oxygen and break down glucose to release energy, just like animals. Photosynthesis (making glucose and releasing oxygen) happens only in light, but respiration never stops. | F35: 5 | G35: 5 | H35: 5 | I35: 2 | J35: Short, accurate, and easy to understand. Could add one sentence naming mitochondria as the site of respiration for learners who want a bit more detail. | K35: No correction needed. (Optional: mention mitochondria as site of respiration.) | L35: OpenStax — "Concepts of Biology (OpenStax) textbook, Chapter on Photosynthesis & Cellular Respiration": it states that Plants are capable of both photosynthesis and cellular respiration, since they contain both chloroplasts and mitochondria. (accessed 2025-11-17); Link: https://openstax.org/books/concepts-biology/pages/5-chapter-summary | M35: No error
D36: Claude | E36: Yes! Plants respire 24/7, just like animals. They break down glucose to produce ATP for energy. This happens in their mitochondria. Photosynthesis (making glucose) happens during the day, but respiration happens constantly to power the plant's activities. | F36: 5 | G36: 5 | H36: 5 | I36: 2 | J36: Accurate and precise — includes ATP and mitochondria which improve scientific clarity; consider adding a one-line plain-English note about ATP for beginners. | K36: No correction needed. | L36: Khan Academy — “Cellular respiration overview” (accessed 2025-11-17) | M36: No error
D37: Copilot | E37: Yes — plants do respire. Just like animals, plants carry out cellular respiration to release energy from glucose. This process happens continuously, day and night, and is essential for their survival. How Plant Respiration Works - Energy release: Plants break down glucose (produced during photosynthesis) in the presence of oxygen to form ATP, the energy currency of cells. - Byproducts: The process produces carbon dioxide and water, just like in animals. - Equation: C6H12O6 + O2 → CO2 + H2O + Energy (ATP) - Gas exchange: Plants don’t have lungs. Instead, they use stomata (tiny pores in leaves) and lenticels (small openings in stems) to exchange gases. Roots also absorb oxygen from air spaces in the soil. | F37: 5 | G37: 5 | H37: 5 | I37: 2 | J37: Thorough and useful (includes equation and gas-exchange routes). More detailed than needed for a quick answer — excellent for learners wanting deeper explanation. | K37: No correction needed. | L37: Same as above | M37: No error
A38: 3 | B38: Mitochondria exist only in animals, not plants. | C38: Do plant cells have mitochondria? | D38: ChatGPT-5 | E38: Yes. Mitochondria are present in plant cells because they need them for respiration, just like animal cells. | F38: 5 | G38: 5 | H38: 5 | I38: 2 | J38: Short & correct and clearly stated. Brief but still complete enough for the question. No unnecessary complexity. | K38: No correction needed. | L38: Khan Academy — “Chloroplasts and mitochondria”(accessed 2025-11-18) ; Link: https://www.khanacademy.org/science/ap-biology/cell-structure-and-function/cell-compartmentalization-and-its-origins/a/chloroplasts-and-mitochondria | M38: No error
D39: Claude | E39: Yes. Plant cells have both chloroplasts (for photosynthesis) AND mitochondria (for cellular respiration). They need mitochondria to break down the glucose they make and convert it into usable ATP energy. | F39: 5 | G39: 5 | H39: 5 | I39: 2 | J39: Correct answer. Added technical terminology (glucose & ATP), which improves clarity; consider adding a one-line plain-English note about ATP for beginners. | K39: No correction needed. | L39: Same as above | M39: No error
D40: Copilot | E40: Yes — plant cells do have mitochondria. They are essential organelles found in all eukaryotic cells, including plants, and they work alongside chloroplasts to keep the cell alive and functioning. Key Facts - Mitochondria are the “powerhouses” of the cell: They carry out cellular respiration, breaking down glucose into ATP (energy) that fuels growth, repair, and other vital processes. - Plant cells contain both mitochondria and chloroplasts: - Chloroplasts capture sunlight and make glucose during photosynthesis. - Mitochondria then use that glucose to produce ATP through respiration. - Complementary roles: Chloroplasts provide the food, mitochondria release the energy from that food. - Structure: Plant mitochondria have double membranes and their own DNA, just like animal mitochondria. | F40: 5 | G40: 5 | H40: 5 | I40: 2 | J40: Thorough and well explaned with extra details (roles of chloroplasts vs mitochondria, structure). More than required for a short answer, but excellent if learner wants deeper understanding. | K40: No correction needed. | L40: Same as above | M40: No error
A41: 4 | B41: Respiration is the same as breathing. | C41: Is cellular respiration the same as breathing? Explain. | D41: ChatGPT-5 | E41: No. Breathing is a physical process of moving air in and out of lungs. Cellular respiration is a chemical process inside cells that releases energy from glucose. | F41: 5 | G41: 5 | H41: 5 | I41: 2 | J41: Short & correct and clearly stated. Brief but still complete enough for the question. No unnecessary complexity. | K41: No correction needed. | L41: Khan Academy: “An introduction to cellular respiration”(accessed 2025-11-18) ; Link: https://www.khanacademy.org/science/hs-bio/x230b3ff252126bb6:energy-and-matter-in-biological-systems/x230b3ff252126bb6:cellular-respiration/a/cellular-respiration-overview | M41: No error
D42: Claude | E42: No, but they're related. Breathing (ventilation) is the physical process of moving air in and out of your lungs Cellular respiration is the chemical process happening inside your cells where glucose and oxygen are converted into ATP, carbon dioxide, and water Breathing gets oxygen to your cells so they can do cellular respiration, and removes the carbon dioxide waste product. | F42: 5 | G42: 5 | H42: 5 | I42: 2 | J42: Accurate and clear; mentions ATP and links the two processes well — good for learners who want the connection. | K42: No correction needed. | L42: khan Academy: "Lesson 6: Cellular respiration" & "Respiartion & breathing" (accessed 2025-11-18) link of video: https://www.khanacademy.org/science/odisha-board-preparation-class-10in/x3c214daca98fdd3d:week-1/x3c214daca98fdd3d:life-processes/v/respiration-breathing | M42: No error
D43: Copilot | E43: No, they’re not the same 🙂 - Breathing (respiration in the lungs) is the physical process of inhaling oxygen and exhaling carbon dioxide. - Cellular respiration happens inside cells, where oxygen is used to break down glucose and release energy in the form of ATP. So, breathing brings oxygen into the body, while cellular respiration uses that oxygen to produce energy. | F43: 5 | G43: 5 | H43: 5 | I43: 2 | J43: Thorough and learner-friendly; explains both processes and their relationship (breathing supplies O₂ for cellular respiration). | K43: No correction needed. | L43: Same as above | M43: No error
A44: 5 | B44: Cells stop functioning when they are not dividing. | C44: Do cells stop carrying out functions when they are not dividing? | D44: ChatGPT-5 | E44: No. Most of a cell’s life is spent not dividing. During that time it is actively doing its normal functions (making proteins, transporting materials, etc.). | F44: 5 | G44: 5 | H44: 5 | I44: 2 | J44: Short & correct and clearly stated. Brief but still complete enough for the question. No unnecessary complexity. | K44: No correction needed. | L44: Khan academy:" Lesson 3: Mitosis" (accessed 2025-11-19)Link: https://www.khanacademy.org/science/telengana-class-11-botany/xdc79b78835d064b7:cell-cycle-and-cell-division/xdc79b78835d064b7:mitosis/a/hs-the-cell-cycle-and-mitosis-review | M44: No error
D45: Claude | E45: No. Cells are constantly active! Most of a cell's life is spent in "interphase" (not dividing), and during this time they're incredibly busy: making proteins, producing energy, transporting materials, responding to signals, repairing damage, and performing their specialized jobs. Division is actually a relatively brief period in a cell's life. | F45: 5 | G45: 5 | H45: 5 | I45: 2 | J45: Accurate and precise. Added technical terminology (Interphase), which improves clarity for learners. | K45: No correction needed. | L45: Same as above | M45: No error
D46: Copilot | E46: No, cells do not stop functioning when they are not dividing 👍 - Cell division is just one part of a cell’s life cycle. - When cells are not dividing, they are usually in a phase called interphase, where they actively carry out their normal functions. - During interphase, cells: - Produce proteins and enzymes - Carry out metabolism (like cellular respiration) - Transport materials in and out - Maintain homeostasis - Prepare for future division if needed So, most of a cell’s life is actually spent not dividing, but still working hard to keep the organism alive. | F46: 5 | G46: 5 | H46: 5 | I46: 2 | J46: Thorough and accurate explanation with extra details. More than required for a short answer, but excellent if learner wants deeper understanding. | K46: No correction needed. | L46: Same as above | M46: No error
A47: 6 | B47: Only animals have enzymes; plants don’t. | C47: Do plants produce enzymes? Why or why not? | D47: ChatGPT-5 | E47: Yes. Plants produce enzymes because all living organisms need enzymes to speed up chemical reactions necessary for survival—photosynthesis, respiration, growth, and more. | F47: 5 | G47: 5 | H47: 5 | I47: 2 | J47: Short & correct and clearly stated. Brief but still complete enough for the question; could include one example enzyme (e.g., Rubisco) to add a concrete detail. | K47: No correction needed. (Optional: add example enzyme, e.g., Rubisco.) | L47: Khan Academy — "lesson4: Photsynthesis"(accessed 2025-11-19); Link: https://www.khanacademy.org/science/ap-biology/cellular-energetics/photosynthesis/a/calvin-cycle(“The Calvin cycle” — describes a specific enzyme RuBisCO used in plant photosynthesis.) | M47: No error
D48: Claude | E48: Yes. Plants produce thousands of enzymes because they need them to catalyze all their chemical reactions—photosynthesis, respiration, digestion of nutrients, building cell walls, producing hormones, and much more. All living organisms need enzymes to function. | F48: 5 | G48: 5 | H48: 5 | I48: 2 | J48: Accurate and precise; Added technical terminology (catalysis etc), which improves scientific clarity. | K48: No correction needed. (Optional: add example enzyme, e.g., Rubisco.) | L48: Same as above | M48: No error
D49: Copilot | E49: Yes, plants do produce enzymes 🌱 - Why? Enzymes are biological catalysts that speed up chemical reactions. Plants need them to survive because almost every process in a plant cell requires enzymes. - Examples of plant enzymes: - Amylase – breaks down starch into sugars. - Rubisco – helps fix carbon dioxide during photosynthesis. - Cellulase – helps remodel cell walls. - Reason: Without enzymes, reactions like photosynthesis, respiration, and nutrient transport would be far too slow to sustain life. So, just like animals and humans, plants rely on enzymes to carry out their essential life processes efficiently. | F49: 5 | G49: 5 | H49: 5 | I49: 2 | J49: Thorough and concrete (lists specific enzymes and functions). More detail than required for a quick answer — very useful for learners wants deeper understanding. | K49: No correction needed. | L49: Same as above | M49: No error
...

Sheet AI model performance summary
A2: AI Model Performance Summary:
A3: AI Model | B3: Avg Accuracy | C3: Avg Clarity | D3: Avg Completeness | E3: Avg Final Score | F3: Observed Errors
A4: ChatGPT-5 | B4: =AVERAGE('AI response evaluation '!F32,'AI response evaluation '!F35,'AI response evaluation '!F38,'AI response evaluation '!F41,'AI response evaluation '!F45,'AI response evaluation '!F47,'AI response evaluation '!F50,'AI response evaluation '!F53,'AI response evaluation '!F56,'AI response evaluation '!F59) -> 4.9 | C4: =AVERAGE('AI response evaluation '!G32,'AI response evaluation '!G35,'AI response evaluation '!G38,'AI response evaluation '!G41,'AI response evaluation '!G45,'AI response evaluation '!G47,'AI response evaluation '!G50,'AI response evaluation '!G53,'AI response evaluation '!G56,'AI response evaluation '!G59) -> 4.8 | D4: =AVERAGE('AI response evaluation '!H32,'AI response evaluation '!H35,'AI response evaluation '!H38,'AI response evaluation '!H41,'AI response evaluation '!H45,'AI response evaluation '!H47,'AI response evaluation '!H50,'AI response evaluation '!H53,'AI response evaluation '!H56,'AI response evaluation '!H59) -> 4.5 | E4: =AVERAGE('AI response evaluation '!I32,'AI response evaluation '!I35,'AI response evaluation '!I38,'AI response evaluation '!I41,'AI response evaluation '!I45,'AI response evaluation '!I47,'AI response evaluation '!I50,'AI response evaluation '!I53,'AI response evaluation '!I56,'AI response evaluation '!I59) -> 1.9 | F4: Oversimplification
A5: Claude | B5: =AVERAGE('AI response evaluation '!F33,'AI response evaluation '!F36,'AI response evaluation '!F39,'AI response evaluation '!F42,'AI response evaluation '!F46,'AI response evaluation '!F48,'AI response evaluation '!F51,'AI response evaluation '!F54,'AI response evaluation '!F57,'AI response evaluation '!F60) -> 5 | C5: =AVERAGE('AI response evaluation '!G33,'AI response evaluation '!G36,'AI response evaluation '!G39,'AI response evaluation '!G42,'AI response evaluation '!G46,'AI response evaluation '!G48,'AI response evaluation '!G51,'AI response evaluation '!G54,'AI response evaluation '!G57,'AI response evaluation '!G60) -> 5 | D5: =AVERAGE('AI response evaluation '!H33,'AI response evaluation '!H36,'AI response evaluation '!H39,'AI response evaluation '!H42,'AI response evaluation '!H46,'AI response evaluation '!H48,'AI response evaluation '!H51,'AI response evaluation '!H54,'AI response evaluation '!H57,'AI response evaluation '!H60) -> 5 | E5: =AVERAGE('AI response evaluation '!I33,'AI response evaluation '!I36,'AI response evaluation '!I39,'AI response evaluation '!I42,'AI response evaluation '!I46,'AI response evaluation '!I48,'AI response evaluation '!I51,'AI response evaluation '!I54,'AI response evaluation '!I57,'AI response evaluation '!I60) -> 2 | F5: No error
A6: Copilot | B6: =AVERAGE('AI response evaluation '!F34,'AI response evaluation '!F37,'AI response evaluation '!F40,'AI response evaluation '!F43,'AI response evaluation '!F47,'AI response evaluation '!F49,'AI response evaluation '!F52,'AI response evaluation '!F55,'AI response evaluation '!F58,'AI response evaluation '!F61) -> 4.9 | C6: =AVERAGE('AI response evaluation '!G34,'AI response evaluation '!G37,'AI response evaluation '!G40,'AI response evaluation '!G43,'AI response evaluation '!G47,'AI response evaluation '!G49,'AI response evaluation '!G52,'AI response evaluation '!G55,'AI response evaluation '!G58,'AI response evaluation '!G61) -> 4.9 | D6: =AVERAGE('AI response evaluation '!H34,'AI response evaluation '!H37,'AI response evaluation '!H40,'AI response evaluation '!H43,'AI response evaluation '!H47,'AI response evaluation '!H49,'AI response evaluation '!H52,'AI response evaluation '!H55,'AI response evaluation '!H58,'AI response evaluation '!H61) -> 4.9 | E6: =AVERAGE('AI response evaluation '!I34,'AI response evaluation '!I37,'AI response evaluation '!I40,'AI response evaluation '!I43,'AI response evaluation '!I47,'AI response evaluation '!I49,'AI response evaluation '!I52,'AI response evaluation '!I55,'AI response evaluation '!I58,'AI response evaluation '!I61) -> 1.9 | F6: Misleading phrasing
A8: Summary of Observed Error Types:
A9: Model | B9: No error | C9: Oversimplification | D9: Misleading phrasing
A10: ChatGPT-5 | B10: =COUNTIFS('AI response evaluation '!D32:D61, "ChatGPT-5", 'AI response evaluation '!M32:M61, "No error") -> 9 | C10: =COUNTIFS('AI response evaluation '!D32:D61, "ChatGPT-5", 'AI response evaluation '!M32:M61, "Oversimplification") -> 1 | D10: =COUNTIFS('AI response evaluation '!D32:D61, "ChatGPT-5", 'AI response evaluation '!M32:M61, "Misleading phrasing") -> 0
A11: Claude | B11: =COUNTIFS('AI response evaluation '!D32:D61, "Claude", 'AI response evaluation '!M32:M61, "No error") -> 10 | C11: =COUNTIFS('AI response evaluation '!D32:D61, "Claude", 'AI response evaluation '!M32:M61, "Oversimplification") -> 0 | D11: =COUNTIFS('AI response evaluation '!D32:D61, "Claude", 'AI response evaluation '!M32:M61, "Misleading phrasing") -> 0
A12: Copilot | B12: =COUNTIFS('AI response evaluation '!D32:D61, "Copilot", 'AI response evaluation '!M32:M61, "No error") -> 9 | C12: =COUNTIFS('AI response evaluation '!D32:D61, "Copilot", 'AI response evaluation '!M32:M61, "Oversimplification") -> 0 | D12: =COUNTIFS('AI response evaluation '!D32:D61, "Copilot", 'AI response evaluation '!M32:M61, "Misleading phrasing") -> 1

Sheet Charts & Observations
A16: Key Observations:
A18: • Claude consistently achieved perfect 5s across accuracy, clarity, and completeness — and received 2/2 scores on all responses.
A20: • ChatGPT-5 showed slightly lower completeness due to occasional oversimplification/ brief responses.
A22: • Copilot performed well overall, but one response had misleading phrasing.
A24: Conclusion:
A26: • Claude ranked highest— fully correct answers, no errors, and maximum score (2) on every question.
A28: • Copilot performed very well and often provided deeper explanations, useful for learning; one response had slightly misleading phrasing.
A30: • ChatGPT-5 performed well overall but but sometimes too brief, which occasionally reduced completeness.
